{
 "cells": [
  {
   "cell_type": "code",
   "execution_count": 1,
   "metadata": {},
   "outputs": [
    {
     "name": "stderr",
     "output_type": "stream",
     "text": [
      "2023/07/28 14:22:25 INFO mlflow.tracking.fluent: Autologging successfully enabled for statsmodels.\n",
      "2023/07/28 14:22:25 INFO mlflow.tracking.fluent: Autologging successfully enabled for xgboost.\n",
      "2023/07/28 14:22:25 INFO mlflow.tracking.fluent: Autologging successfully enabled for sklearn.\n"
     ]
    }
   ],
   "source": [
    "import os\n",
    "import pandas as pd\n",
    "from xgboost import XGBClassifier\n",
    "from funkcije import *"
   ]
  },
  {
   "cell_type": "code",
   "execution_count": 2,
   "metadata": {},
   "outputs": [],
   "source": [
    "nemci = pd.read_csv(\"baza_labelirana.csv\")"
   ]
  },
  {
   "cell_type": "code",
   "execution_count": 9,
   "metadata": {},
   "outputs": [],
   "source": [
    "# X = nemci[['hurstovi', 'duzine', 'odnos_tišine_i_govora',\n",
    "#  'najduža_priča', 'zcr_prosek', 'zcr_min', 'zcr_max', 'zcr_med', 'zcr_stdev',\n",
    "#  'pitch_prosek', 'pitch_min', 'pitch_max', 'pitch_med', 'pitch_stdev',\n",
    "#  'energija_prosek', 'energija_min', 'energija_max', 'energija_stdev',\n",
    "#  'eng_bez_tis', 'eng_bez_tis_avg', 'eng_bez_tis_min', 'eng_bez_tis_max',\n",
    "#  'eng_bez_tis_med', 'eng_bez_tis_stdev', 'energija_ukupna',\n",
    "X = nemci[['mfcc_mean_1',\n",
    "  'mfcc_min_1', 'mfcc_max_1', 'mfcc_med_1', 'mfcc_var_1', 'mfcc_mean_2',\n",
    "  'mfcc_min_2', 'mfcc_max_2', 'mfcc_med_2', 'mfcc_var_2', 'mfcc_mean_3',\n",
    "  'mfcc_min_3', 'mfcc_max_3', 'mfcc_med_3', 'mfcc_var_3', 'mfcc_mean_4',\n",
    "  'mfcc_min_4', 'mfcc_max_4', 'mfcc_med_4', 'mfcc_var_4', 'mfcc_mean_5',\n",
    "  'mfcc_min_5', 'mfcc_max_5', 'mfcc_med_5', 'mfcc_var_5', 'mfcc_mean_6',\n",
    "  'mfcc_min_6', 'mfcc_max_6', 'mfcc_med_6', 'mfcc_var_6', 'mfcc_mean_7',\n",
    "  'mfcc_min_7', 'mfcc_max_7', 'mfcc_med_7', 'mfcc_var_7', 'mfcc_mean_8',\n",
    "  'mfcc_min_8', 'mfcc_max_8', 'mfcc_med_8', 'mfcc_var_8', 'mfcc_mean_9',\n",
    "  'mfcc_min_9', 'mfcc_max_9', 'mfcc_med_9', 'mfcc_var_9', 'mfcc_mean_10',\n",
    "  'mfcc_min_10', 'mfcc_max_10', 'mfcc_med_10', 'mfcc_var_10', 'mfcc_mean_11',\n",
    "  'mfcc_min_11', 'mfcc_max_11', 'mfcc_med_11', 'mfcc_var_11', 'mfcc_mean_12',\n",
    "  'mfcc_min_12', 'mfcc_max_12', 'mfcc_med_12', 'mfcc_var_12', 'mfcc_mean_13',\n",
    "  'mfcc_min_13', 'mfcc_max_13', 'mfcc_med_13', 'mfcc_var_13', 'mfcc_mean_14',\n",
    "  'mfcc_min_14', 'mfcc_max_14', 'mfcc_med_14', 'mfcc_var_14', 'mfcc_mean_15',\n",
    "  'mfcc_min_15', 'mfcc_max_15', 'mfcc_med_15', 'mfcc_var_15', 'mfcc_mean_16',\n",
    "  'mfcc_min_16', 'mfcc_max_16', 'mfcc_med_16', 'mfcc_var_16', 'mfcc_mean_17',\n",
    "  'mfcc_min_17', 'mfcc_max_17', 'mfcc_med_17', 'mfcc_var_17', 'mfcc_mean_18',\n",
    "  'mfcc_min_18', 'mfcc_max_18', 'mfcc_med_18', 'mfcc_var_18', 'mfcc_mean_19',\n",
    "  'mfcc_min_19', 'mfcc_max_19', 'mfcc_med_19', 'mfcc_var_19', 'mfcc_mean_20',\n",
    "  'mfcc_min_20', 'mfcc_max_20', 'mfcc_med_20', 'mfcc_var_20']]\n",
    "\n",
    "y = nemci[[\"sve\"]]\n",
    "\n",
    "X = X.values\n",
    "y = y.values"
   ]
  },
  {
   "cell_type": "code",
   "execution_count": 10,
   "metadata": {},
   "outputs": [
    {
     "name": "stderr",
     "output_type": "stream",
     "text": [
      "2023/07/28 14:26:54 INFO mlflow.utils.autologging_utils: Created MLflow autologging run with ID 'e7d4aaa78431416892d9f6f01bc13e36', which will track hyperparameters, performance metrics, model artifacts, and lineage information for the current xgboost workflow\n"
     ]
    },
    {
     "name": "stderr",
     "output_type": "stream",
     "text": [
      "2023/07/28 14:26:58 ERROR mlflow.xgboost: Failed to log feature importance plot. XGBoost autologging will ignore the failure and continue. Exception: \n",
      "Traceback (most recent call last):\n",
      "  File \"/home/zarko/.local/lib/python3.9/site-packages/mlflow/xgboost/__init__.py\", line 665, in train_impl\n",
      "    log_feature_importance_plot(features, importance, imp_type)\n",
      "  File \"/home/zarko/.local/lib/python3.9/site-packages/mlflow/xgboost/__init__.py\", line 564, in log_feature_importance_plot\n",
      "    mlflow.log_artifact(filepath)\n",
      "  File \"/home/zarko/.local/lib/python3.9/site-packages/mlflow/tracking/fluent.py\", line 877, in log_artifact\n",
      "    MlflowClient().log_artifact(run_id, local_path, artifact_path)\n",
      "  File \"/home/zarko/.local/lib/python3.9/site-packages/mlflow/tracking/client.py\", line 1091, in log_artifact\n",
      "    self._tracking_client.log_artifact(run_id, local_path, artifact_path)\n",
      "  File \"/home/zarko/.local/lib/python3.9/site-packages/mlflow/tracking/_tracking_service/client.py\", line 448, in log_artifact\n",
      "    artifact_repo = self._get_artifact_repo(run_id)\n",
      "  File \"/home/zarko/.local/lib/python3.9/site-packages/mlflow/tracking/_tracking_service/client.py\", line 433, in _get_artifact_repo\n",
      "    artifact_repo = get_artifact_repository(artifact_uri)\n",
      "  File \"/home/zarko/.local/lib/python3.9/site-packages/mlflow/store/artifact/artifact_repository_registry.py\", line 114, in get_artifact_repository\n",
      "    return _artifact_repository_registry.get_artifact_repository(artifact_uri)\n",
      "  File \"/home/zarko/.local/lib/python3.9/site-packages/mlflow/store/artifact/artifact_repository_registry.py\", line 72, in get_artifact_repository\n",
      "    return repository(artifact_uri)\n",
      "  File \"/home/zarko/.local/lib/python3.9/site-packages/mlflow/store/artifact/mlflow_artifacts_repo.py\", line 45, in __init__\n",
      "    super().__init__(self.resolve_uri(artifact_uri, get_tracking_uri()))\n",
      "  File \"/home/zarko/.local/lib/python3.9/site-packages/mlflow/store/artifact/mlflow_artifacts_repo.py\", line 59, in resolve_uri\n",
      "    _validate_uri_scheme(track_parse.scheme)\n",
      "  File \"/home/zarko/.local/lib/python3.9/site-packages/mlflow/store/artifact/mlflow_artifacts_repo.py\", line 35, in _validate_uri_scheme\n",
      "    raise MlflowException(\n",
      "mlflow.exceptions.MlflowException: The configured tracking uri scheme: 'file' is invalid for use with the proxy mlflow-artifact scheme. The allowed tracking schemes are: {'http', 'https'}\n",
      "2023/07/28 14:26:58 WARNING mlflow.utils.autologging_utils: Encountered unexpected error during xgboost autologging: The configured tracking uri scheme: 'file' is invalid for use with the proxy mlflow-artifact scheme. The allowed tracking schemes are: {'http', 'https'}\n",
      "2023/07/28 14:26:59 WARNING mlflow.utils.autologging_utils: Encountered unexpected error during xgboost autologging: The configured tracking uri scheme: 'file' is invalid for use with the proxy mlflow-artifact scheme. The allowed tracking schemes are: {'http', 'https'}\n",
      "2023/07/28 14:27:01 ERROR mlflow.xgboost: Failed to log feature importance plot. XGBoost autologging will ignore the failure and continue. Exception: \n",
      "Traceback (most recent call last):\n",
      "  File \"/home/zarko/.local/lib/python3.9/site-packages/mlflow/xgboost/__init__.py\", line 665, in train_impl\n",
      "    log_feature_importance_plot(features, importance, imp_type)\n",
      "  File \"/home/zarko/.local/lib/python3.9/site-packages/mlflow/xgboost/__init__.py\", line 564, in log_feature_importance_plot\n",
      "    mlflow.log_artifact(filepath)\n",
      "  File \"/home/zarko/.local/lib/python3.9/site-packages/mlflow/tracking/fluent.py\", line 877, in log_artifact\n",
      "    MlflowClient().log_artifact(run_id, local_path, artifact_path)\n",
      "  File \"/home/zarko/.local/lib/python3.9/site-packages/mlflow/tracking/client.py\", line 1091, in log_artifact\n",
      "    self._tracking_client.log_artifact(run_id, local_path, artifact_path)\n",
      "  File \"/home/zarko/.local/lib/python3.9/site-packages/mlflow/tracking/_tracking_service/client.py\", line 448, in log_artifact\n",
      "    artifact_repo = self._get_artifact_repo(run_id)\n",
      "  File \"/home/zarko/.local/lib/python3.9/site-packages/mlflow/tracking/_tracking_service/client.py\", line 433, in _get_artifact_repo\n",
      "    artifact_repo = get_artifact_repository(artifact_uri)\n",
      "  File \"/home/zarko/.local/lib/python3.9/site-packages/mlflow/store/artifact/artifact_repository_registry.py\", line 114, in get_artifact_repository\n",
      "    return _artifact_repository_registry.get_artifact_repository(artifact_uri)\n",
      "  File \"/home/zarko/.local/lib/python3.9/site-packages/mlflow/store/artifact/artifact_repository_registry.py\", line 72, in get_artifact_repository\n",
      "    return repository(artifact_uri)\n",
      "  File \"/home/zarko/.local/lib/python3.9/site-packages/mlflow/store/artifact/mlflow_artifacts_repo.py\", line 45, in __init__\n",
      "    super().__init__(self.resolve_uri(artifact_uri, get_tracking_uri()))\n",
      "  File \"/home/zarko/.local/lib/python3.9/site-packages/mlflow/store/artifact/mlflow_artifacts_repo.py\", line 59, in resolve_uri\n",
      "    _validate_uri_scheme(track_parse.scheme)\n",
      "  File \"/home/zarko/.local/lib/python3.9/site-packages/mlflow/store/artifact/mlflow_artifacts_repo.py\", line 35, in _validate_uri_scheme\n",
      "    raise MlflowException(\n",
      "mlflow.exceptions.MlflowException: The configured tracking uri scheme: 'file' is invalid for use with the proxy mlflow-artifact scheme. The allowed tracking schemes are: {'http', 'https'}\n",
      "2023/07/28 14:27:01 WARNING mlflow.utils.autologging_utils: Encountered unexpected error during xgboost autologging: The configured tracking uri scheme: 'file' is invalid for use with the proxy mlflow-artifact scheme. The allowed tracking schemes are: {'http', 'https'}\n",
      "2023/07/28 14:27:03 WARNING mlflow.utils.autologging_utils: Encountered unexpected error during xgboost autologging: The configured tracking uri scheme: 'file' is invalid for use with the proxy mlflow-artifact scheme. The allowed tracking schemes are: {'http', 'https'}\n",
      "2023/07/28 14:27:05 ERROR mlflow.xgboost: Failed to log feature importance plot. XGBoost autologging will ignore the failure and continue. Exception: \n",
      "Traceback (most recent call last):\n",
      "  File \"/home/zarko/.local/lib/python3.9/site-packages/mlflow/xgboost/__init__.py\", line 665, in train_impl\n",
      "    log_feature_importance_plot(features, importance, imp_type)\n",
      "  File \"/home/zarko/.local/lib/python3.9/site-packages/mlflow/xgboost/__init__.py\", line 564, in log_feature_importance_plot\n",
      "    mlflow.log_artifact(filepath)\n",
      "  File \"/home/zarko/.local/lib/python3.9/site-packages/mlflow/tracking/fluent.py\", line 877, in log_artifact\n",
      "    MlflowClient().log_artifact(run_id, local_path, artifact_path)\n",
      "  File \"/home/zarko/.local/lib/python3.9/site-packages/mlflow/tracking/client.py\", line 1091, in log_artifact\n",
      "    self._tracking_client.log_artifact(run_id, local_path, artifact_path)\n",
      "  File \"/home/zarko/.local/lib/python3.9/site-packages/mlflow/tracking/_tracking_service/client.py\", line 448, in log_artifact\n",
      "    artifact_repo = self._get_artifact_repo(run_id)\n",
      "  File \"/home/zarko/.local/lib/python3.9/site-packages/mlflow/tracking/_tracking_service/client.py\", line 433, in _get_artifact_repo\n",
      "    artifact_repo = get_artifact_repository(artifact_uri)\n",
      "  File \"/home/zarko/.local/lib/python3.9/site-packages/mlflow/store/artifact/artifact_repository_registry.py\", line 114, in get_artifact_repository\n",
      "    return _artifact_repository_registry.get_artifact_repository(artifact_uri)\n",
      "  File \"/home/zarko/.local/lib/python3.9/site-packages/mlflow/store/artifact/artifact_repository_registry.py\", line 72, in get_artifact_repository\n",
      "    return repository(artifact_uri)\n",
      "  File \"/home/zarko/.local/lib/python3.9/site-packages/mlflow/store/artifact/mlflow_artifacts_repo.py\", line 45, in __init__\n",
      "    super().__init__(self.resolve_uri(artifact_uri, get_tracking_uri()))\n",
      "  File \"/home/zarko/.local/lib/python3.9/site-packages/mlflow/store/artifact/mlflow_artifacts_repo.py\", line 59, in resolve_uri\n",
      "    _validate_uri_scheme(track_parse.scheme)\n",
      "  File \"/home/zarko/.local/lib/python3.9/site-packages/mlflow/store/artifact/mlflow_artifacts_repo.py\", line 35, in _validate_uri_scheme\n",
      "    raise MlflowException(\n",
      "mlflow.exceptions.MlflowException: The configured tracking uri scheme: 'file' is invalid for use with the proxy mlflow-artifact scheme. The allowed tracking schemes are: {'http', 'https'}\n",
      "2023/07/28 14:27:05 WARNING mlflow.utils.autologging_utils: Encountered unexpected error during xgboost autologging: The configured tracking uri scheme: 'file' is invalid for use with the proxy mlflow-artifact scheme. The allowed tracking schemes are: {'http', 'https'}\n",
      "2023/07/28 14:27:06 WARNING mlflow.utils.autologging_utils: Encountered unexpected error during xgboost autologging: The configured tracking uri scheme: 'file' is invalid for use with the proxy mlflow-artifact scheme. The allowed tracking schemes are: {'http', 'https'}\n",
      "2023/07/28 14:27:09 ERROR mlflow.xgboost: Failed to log feature importance plot. XGBoost autologging will ignore the failure and continue. Exception: \n",
      "Traceback (most recent call last):\n",
      "  File \"/home/zarko/.local/lib/python3.9/site-packages/mlflow/xgboost/__init__.py\", line 665, in train_impl\n",
      "    log_feature_importance_plot(features, importance, imp_type)\n",
      "  File \"/home/zarko/.local/lib/python3.9/site-packages/mlflow/xgboost/__init__.py\", line 564, in log_feature_importance_plot\n",
      "    mlflow.log_artifact(filepath)\n",
      "  File \"/home/zarko/.local/lib/python3.9/site-packages/mlflow/tracking/fluent.py\", line 877, in log_artifact\n",
      "    MlflowClient().log_artifact(run_id, local_path, artifact_path)\n",
      "  File \"/home/zarko/.local/lib/python3.9/site-packages/mlflow/tracking/client.py\", line 1091, in log_artifact\n",
      "    self._tracking_client.log_artifact(run_id, local_path, artifact_path)\n",
      "  File \"/home/zarko/.local/lib/python3.9/site-packages/mlflow/tracking/_tracking_service/client.py\", line 448, in log_artifact\n",
      "    artifact_repo = self._get_artifact_repo(run_id)\n",
      "  File \"/home/zarko/.local/lib/python3.9/site-packages/mlflow/tracking/_tracking_service/client.py\", line 433, in _get_artifact_repo\n",
      "    artifact_repo = get_artifact_repository(artifact_uri)\n",
      "  File \"/home/zarko/.local/lib/python3.9/site-packages/mlflow/store/artifact/artifact_repository_registry.py\", line 114, in get_artifact_repository\n",
      "    return _artifact_repository_registry.get_artifact_repository(artifact_uri)\n",
      "  File \"/home/zarko/.local/lib/python3.9/site-packages/mlflow/store/artifact/artifact_repository_registry.py\", line 72, in get_artifact_repository\n",
      "    return repository(artifact_uri)\n",
      "  File \"/home/zarko/.local/lib/python3.9/site-packages/mlflow/store/artifact/mlflow_artifacts_repo.py\", line 45, in __init__\n",
      "    super().__init__(self.resolve_uri(artifact_uri, get_tracking_uri()))\n",
      "  File \"/home/zarko/.local/lib/python3.9/site-packages/mlflow/store/artifact/mlflow_artifacts_repo.py\", line 59, in resolve_uri\n",
      "    _validate_uri_scheme(track_parse.scheme)\n",
      "  File \"/home/zarko/.local/lib/python3.9/site-packages/mlflow/store/artifact/mlflow_artifacts_repo.py\", line 35, in _validate_uri_scheme\n",
      "    raise MlflowException(\n",
      "mlflow.exceptions.MlflowException: The configured tracking uri scheme: 'file' is invalid for use with the proxy mlflow-artifact scheme. The allowed tracking schemes are: {'http', 'https'}\n",
      "2023/07/28 14:27:09 WARNING mlflow.utils.autologging_utils: Encountered unexpected error during xgboost autologging: The configured tracking uri scheme: 'file' is invalid for use with the proxy mlflow-artifact scheme. The allowed tracking schemes are: {'http', 'https'}\n",
      "2023/07/28 14:27:10 WARNING mlflow.utils.autologging_utils: Encountered unexpected error during xgboost autologging: The configured tracking uri scheme: 'file' is invalid for use with the proxy mlflow-artifact scheme. The allowed tracking schemes are: {'http', 'https'}\n",
      "2023/07/28 14:27:12 ERROR mlflow.xgboost: Failed to log feature importance plot. XGBoost autologging will ignore the failure and continue. Exception: \n",
      "Traceback (most recent call last):\n",
      "  File \"/home/zarko/.local/lib/python3.9/site-packages/mlflow/xgboost/__init__.py\", line 665, in train_impl\n",
      "    log_feature_importance_plot(features, importance, imp_type)\n",
      "  File \"/home/zarko/.local/lib/python3.9/site-packages/mlflow/xgboost/__init__.py\", line 564, in log_feature_importance_plot\n",
      "    mlflow.log_artifact(filepath)\n",
      "  File \"/home/zarko/.local/lib/python3.9/site-packages/mlflow/tracking/fluent.py\", line 877, in log_artifact\n",
      "    MlflowClient().log_artifact(run_id, local_path, artifact_path)\n",
      "  File \"/home/zarko/.local/lib/python3.9/site-packages/mlflow/tracking/client.py\", line 1091, in log_artifact\n",
      "    self._tracking_client.log_artifact(run_id, local_path, artifact_path)\n",
      "  File \"/home/zarko/.local/lib/python3.9/site-packages/mlflow/tracking/_tracking_service/client.py\", line 448, in log_artifact\n",
      "    artifact_repo = self._get_artifact_repo(run_id)\n",
      "  File \"/home/zarko/.local/lib/python3.9/site-packages/mlflow/tracking/_tracking_service/client.py\", line 433, in _get_artifact_repo\n",
      "    artifact_repo = get_artifact_repository(artifact_uri)\n",
      "  File \"/home/zarko/.local/lib/python3.9/site-packages/mlflow/store/artifact/artifact_repository_registry.py\", line 114, in get_artifact_repository\n",
      "    return _artifact_repository_registry.get_artifact_repository(artifact_uri)\n",
      "  File \"/home/zarko/.local/lib/python3.9/site-packages/mlflow/store/artifact/artifact_repository_registry.py\", line 72, in get_artifact_repository\n",
      "    return repository(artifact_uri)\n",
      "  File \"/home/zarko/.local/lib/python3.9/site-packages/mlflow/store/artifact/mlflow_artifacts_repo.py\", line 45, in __init__\n",
      "    super().__init__(self.resolve_uri(artifact_uri, get_tracking_uri()))\n",
      "  File \"/home/zarko/.local/lib/python3.9/site-packages/mlflow/store/artifact/mlflow_artifacts_repo.py\", line 59, in resolve_uri\n",
      "    _validate_uri_scheme(track_parse.scheme)\n",
      "  File \"/home/zarko/.local/lib/python3.9/site-packages/mlflow/store/artifact/mlflow_artifacts_repo.py\", line 35, in _validate_uri_scheme\n",
      "    raise MlflowException(\n",
      "mlflow.exceptions.MlflowException: The configured tracking uri scheme: 'file' is invalid for use with the proxy mlflow-artifact scheme. The allowed tracking schemes are: {'http', 'https'}\n",
      "2023/07/28 14:27:12 WARNING mlflow.utils.autologging_utils: Encountered unexpected error during xgboost autologging: The configured tracking uri scheme: 'file' is invalid for use with the proxy mlflow-artifact scheme. The allowed tracking schemes are: {'http', 'https'}\n",
      "2023/07/28 14:27:14 WARNING mlflow.utils.autologging_utils: Encountered unexpected error during xgboost autologging: The configured tracking uri scheme: 'file' is invalid for use with the proxy mlflow-artifact scheme. The allowed tracking schemes are: {'http', 'https'}\n",
      "2023/07/28 14:27:15 ERROR mlflow.xgboost: Failed to log feature importance plot. XGBoost autologging will ignore the failure and continue. Exception: \n",
      "Traceback (most recent call last):\n",
      "  File \"/home/zarko/.local/lib/python3.9/site-packages/mlflow/xgboost/__init__.py\", line 665, in train_impl\n",
      "    log_feature_importance_plot(features, importance, imp_type)\n",
      "  File \"/home/zarko/.local/lib/python3.9/site-packages/mlflow/xgboost/__init__.py\", line 564, in log_feature_importance_plot\n",
      "    mlflow.log_artifact(filepath)\n",
      "  File \"/home/zarko/.local/lib/python3.9/site-packages/mlflow/tracking/fluent.py\", line 877, in log_artifact\n",
      "    MlflowClient().log_artifact(run_id, local_path, artifact_path)\n",
      "  File \"/home/zarko/.local/lib/python3.9/site-packages/mlflow/tracking/client.py\", line 1091, in log_artifact\n",
      "    self._tracking_client.log_artifact(run_id, local_path, artifact_path)\n",
      "  File \"/home/zarko/.local/lib/python3.9/site-packages/mlflow/tracking/_tracking_service/client.py\", line 448, in log_artifact\n",
      "    artifact_repo = self._get_artifact_repo(run_id)\n",
      "  File \"/home/zarko/.local/lib/python3.9/site-packages/mlflow/tracking/_tracking_service/client.py\", line 433, in _get_artifact_repo\n",
      "    artifact_repo = get_artifact_repository(artifact_uri)\n",
      "  File \"/home/zarko/.local/lib/python3.9/site-packages/mlflow/store/artifact/artifact_repository_registry.py\", line 114, in get_artifact_repository\n",
      "    return _artifact_repository_registry.get_artifact_repository(artifact_uri)\n",
      "  File \"/home/zarko/.local/lib/python3.9/site-packages/mlflow/store/artifact/artifact_repository_registry.py\", line 72, in get_artifact_repository\n",
      "    return repository(artifact_uri)\n",
      "  File \"/home/zarko/.local/lib/python3.9/site-packages/mlflow/store/artifact/mlflow_artifacts_repo.py\", line 45, in __init__\n",
      "    super().__init__(self.resolve_uri(artifact_uri, get_tracking_uri()))\n",
      "  File \"/home/zarko/.local/lib/python3.9/site-packages/mlflow/store/artifact/mlflow_artifacts_repo.py\", line 59, in resolve_uri\n",
      "    _validate_uri_scheme(track_parse.scheme)\n",
      "  File \"/home/zarko/.local/lib/python3.9/site-packages/mlflow/store/artifact/mlflow_artifacts_repo.py\", line 35, in _validate_uri_scheme\n",
      "    raise MlflowException(\n",
      "mlflow.exceptions.MlflowException: The configured tracking uri scheme: 'file' is invalid for use with the proxy mlflow-artifact scheme. The allowed tracking schemes are: {'http', 'https'}\n",
      "2023/07/28 14:27:15 WARNING mlflow.utils.autologging_utils: Encountered unexpected error during xgboost autologging: The configured tracking uri scheme: 'file' is invalid for use with the proxy mlflow-artifact scheme. The allowed tracking schemes are: {'http', 'https'}\n",
      "2023/07/28 14:27:17 WARNING mlflow.utils.autologging_utils: Encountered unexpected error during xgboost autologging: The configured tracking uri scheme: 'file' is invalid for use with the proxy mlflow-artifact scheme. The allowed tracking schemes are: {'http', 'https'}\n",
      "2023/07/28 14:27:19 ERROR mlflow.xgboost: Failed to log feature importance plot. XGBoost autologging will ignore the failure and continue. Exception: \n",
      "Traceback (most recent call last):\n",
      "  File \"/home/zarko/.local/lib/python3.9/site-packages/mlflow/xgboost/__init__.py\", line 665, in train_impl\n",
      "    log_feature_importance_plot(features, importance, imp_type)\n",
      "  File \"/home/zarko/.local/lib/python3.9/site-packages/mlflow/xgboost/__init__.py\", line 564, in log_feature_importance_plot\n",
      "    mlflow.log_artifact(filepath)\n",
      "  File \"/home/zarko/.local/lib/python3.9/site-packages/mlflow/tracking/fluent.py\", line 877, in log_artifact\n",
      "    MlflowClient().log_artifact(run_id, local_path, artifact_path)\n",
      "  File \"/home/zarko/.local/lib/python3.9/site-packages/mlflow/tracking/client.py\", line 1091, in log_artifact\n",
      "    self._tracking_client.log_artifact(run_id, local_path, artifact_path)\n",
      "  File \"/home/zarko/.local/lib/python3.9/site-packages/mlflow/tracking/_tracking_service/client.py\", line 448, in log_artifact\n",
      "    artifact_repo = self._get_artifact_repo(run_id)\n",
      "  File \"/home/zarko/.local/lib/python3.9/site-packages/mlflow/tracking/_tracking_service/client.py\", line 433, in _get_artifact_repo\n",
      "    artifact_repo = get_artifact_repository(artifact_uri)\n",
      "  File \"/home/zarko/.local/lib/python3.9/site-packages/mlflow/store/artifact/artifact_repository_registry.py\", line 114, in get_artifact_repository\n",
      "    return _artifact_repository_registry.get_artifact_repository(artifact_uri)\n",
      "  File \"/home/zarko/.local/lib/python3.9/site-packages/mlflow/store/artifact/artifact_repository_registry.py\", line 72, in get_artifact_repository\n",
      "    return repository(artifact_uri)\n",
      "  File \"/home/zarko/.local/lib/python3.9/site-packages/mlflow/store/artifact/mlflow_artifacts_repo.py\", line 45, in __init__\n",
      "    super().__init__(self.resolve_uri(artifact_uri, get_tracking_uri()))\n",
      "  File \"/home/zarko/.local/lib/python3.9/site-packages/mlflow/store/artifact/mlflow_artifacts_repo.py\", line 59, in resolve_uri\n",
      "    _validate_uri_scheme(track_parse.scheme)\n",
      "  File \"/home/zarko/.local/lib/python3.9/site-packages/mlflow/store/artifact/mlflow_artifacts_repo.py\", line 35, in _validate_uri_scheme\n",
      "    raise MlflowException(\n",
      "mlflow.exceptions.MlflowException: The configured tracking uri scheme: 'file' is invalid for use with the proxy mlflow-artifact scheme. The allowed tracking schemes are: {'http', 'https'}\n",
      "2023/07/28 14:27:19 WARNING mlflow.utils.autologging_utils: Encountered unexpected error during xgboost autologging: The configured tracking uri scheme: 'file' is invalid for use with the proxy mlflow-artifact scheme. The allowed tracking schemes are: {'http', 'https'}\n",
      "2023/07/28 14:27:21 WARNING mlflow.utils.autologging_utils: Encountered unexpected error during xgboost autologging: The configured tracking uri scheme: 'file' is invalid for use with the proxy mlflow-artifact scheme. The allowed tracking schemes are: {'http', 'https'}\n",
      "2023/07/28 14:27:24 ERROR mlflow.xgboost: Failed to log feature importance plot. XGBoost autologging will ignore the failure and continue. Exception: \n",
      "Traceback (most recent call last):\n",
      "  File \"/home/zarko/.local/lib/python3.9/site-packages/mlflow/xgboost/__init__.py\", line 665, in train_impl\n",
      "    log_feature_importance_plot(features, importance, imp_type)\n",
      "  File \"/home/zarko/.local/lib/python3.9/site-packages/mlflow/xgboost/__init__.py\", line 564, in log_feature_importance_plot\n",
      "    mlflow.log_artifact(filepath)\n",
      "  File \"/home/zarko/.local/lib/python3.9/site-packages/mlflow/tracking/fluent.py\", line 877, in log_artifact\n",
      "    MlflowClient().log_artifact(run_id, local_path, artifact_path)\n",
      "  File \"/home/zarko/.local/lib/python3.9/site-packages/mlflow/tracking/client.py\", line 1091, in log_artifact\n",
      "    self._tracking_client.log_artifact(run_id, local_path, artifact_path)\n",
      "  File \"/home/zarko/.local/lib/python3.9/site-packages/mlflow/tracking/_tracking_service/client.py\", line 448, in log_artifact\n",
      "    artifact_repo = self._get_artifact_repo(run_id)\n",
      "  File \"/home/zarko/.local/lib/python3.9/site-packages/mlflow/tracking/_tracking_service/client.py\", line 433, in _get_artifact_repo\n",
      "    artifact_repo = get_artifact_repository(artifact_uri)\n",
      "  File \"/home/zarko/.local/lib/python3.9/site-packages/mlflow/store/artifact/artifact_repository_registry.py\", line 114, in get_artifact_repository\n",
      "    return _artifact_repository_registry.get_artifact_repository(artifact_uri)\n",
      "  File \"/home/zarko/.local/lib/python3.9/site-packages/mlflow/store/artifact/artifact_repository_registry.py\", line 72, in get_artifact_repository\n",
      "    return repository(artifact_uri)\n",
      "  File \"/home/zarko/.local/lib/python3.9/site-packages/mlflow/store/artifact/mlflow_artifacts_repo.py\", line 45, in __init__\n",
      "    super().__init__(self.resolve_uri(artifact_uri, get_tracking_uri()))\n",
      "  File \"/home/zarko/.local/lib/python3.9/site-packages/mlflow/store/artifact/mlflow_artifacts_repo.py\", line 59, in resolve_uri\n",
      "    _validate_uri_scheme(track_parse.scheme)\n",
      "  File \"/home/zarko/.local/lib/python3.9/site-packages/mlflow/store/artifact/mlflow_artifacts_repo.py\", line 35, in _validate_uri_scheme\n",
      "    raise MlflowException(\n",
      "mlflow.exceptions.MlflowException: The configured tracking uri scheme: 'file' is invalid for use with the proxy mlflow-artifact scheme. The allowed tracking schemes are: {'http', 'https'}\n",
      "2023/07/28 14:27:24 WARNING mlflow.utils.autologging_utils: Encountered unexpected error during xgboost autologging: The configured tracking uri scheme: 'file' is invalid for use with the proxy mlflow-artifact scheme. The allowed tracking schemes are: {'http', 'https'}\n",
      "2023/07/28 14:27:26 WARNING mlflow.utils.autologging_utils: Encountered unexpected error during xgboost autologging: The configured tracking uri scheme: 'file' is invalid for use with the proxy mlflow-artifact scheme. The allowed tracking schemes are: {'http', 'https'}\n",
      "2023/07/28 14:27:27 ERROR mlflow.xgboost: Failed to log feature importance plot. XGBoost autologging will ignore the failure and continue. Exception: \n",
      "Traceback (most recent call last):\n",
      "  File \"/home/zarko/.local/lib/python3.9/site-packages/mlflow/xgboost/__init__.py\", line 665, in train_impl\n",
      "    log_feature_importance_plot(features, importance, imp_type)\n",
      "  File \"/home/zarko/.local/lib/python3.9/site-packages/mlflow/xgboost/__init__.py\", line 564, in log_feature_importance_plot\n",
      "    mlflow.log_artifact(filepath)\n",
      "  File \"/home/zarko/.local/lib/python3.9/site-packages/mlflow/tracking/fluent.py\", line 877, in log_artifact\n",
      "    MlflowClient().log_artifact(run_id, local_path, artifact_path)\n",
      "  File \"/home/zarko/.local/lib/python3.9/site-packages/mlflow/tracking/client.py\", line 1091, in log_artifact\n",
      "    self._tracking_client.log_artifact(run_id, local_path, artifact_path)\n",
      "  File \"/home/zarko/.local/lib/python3.9/site-packages/mlflow/tracking/_tracking_service/client.py\", line 448, in log_artifact\n",
      "    artifact_repo = self._get_artifact_repo(run_id)\n",
      "  File \"/home/zarko/.local/lib/python3.9/site-packages/mlflow/tracking/_tracking_service/client.py\", line 433, in _get_artifact_repo\n",
      "    artifact_repo = get_artifact_repository(artifact_uri)\n",
      "  File \"/home/zarko/.local/lib/python3.9/site-packages/mlflow/store/artifact/artifact_repository_registry.py\", line 114, in get_artifact_repository\n",
      "    return _artifact_repository_registry.get_artifact_repository(artifact_uri)\n",
      "  File \"/home/zarko/.local/lib/python3.9/site-packages/mlflow/store/artifact/artifact_repository_registry.py\", line 72, in get_artifact_repository\n",
      "    return repository(artifact_uri)\n",
      "  File \"/home/zarko/.local/lib/python3.9/site-packages/mlflow/store/artifact/mlflow_artifacts_repo.py\", line 45, in __init__\n",
      "    super().__init__(self.resolve_uri(artifact_uri, get_tracking_uri()))\n",
      "  File \"/home/zarko/.local/lib/python3.9/site-packages/mlflow/store/artifact/mlflow_artifacts_repo.py\", line 59, in resolve_uri\n",
      "    _validate_uri_scheme(track_parse.scheme)\n",
      "  File \"/home/zarko/.local/lib/python3.9/site-packages/mlflow/store/artifact/mlflow_artifacts_repo.py\", line 35, in _validate_uri_scheme\n",
      "    raise MlflowException(\n",
      "mlflow.exceptions.MlflowException: The configured tracking uri scheme: 'file' is invalid for use with the proxy mlflow-artifact scheme. The allowed tracking schemes are: {'http', 'https'}\n",
      "2023/07/28 14:27:27 WARNING mlflow.utils.autologging_utils: Encountered unexpected error during xgboost autologging: The configured tracking uri scheme: 'file' is invalid for use with the proxy mlflow-artifact scheme. The allowed tracking schemes are: {'http', 'https'}\n",
      "2023/07/28 14:27:29 WARNING mlflow.utils.autologging_utils: Encountered unexpected error during xgboost autologging: The configured tracking uri scheme: 'file' is invalid for use with the proxy mlflow-artifact scheme. The allowed tracking schemes are: {'http', 'https'}\n",
      "2023/07/28 14:27:31 ERROR mlflow.xgboost: Failed to log feature importance plot. XGBoost autologging will ignore the failure and continue. Exception: \n",
      "Traceback (most recent call last):\n",
      "  File \"/home/zarko/.local/lib/python3.9/site-packages/mlflow/xgboost/__init__.py\", line 665, in train_impl\n",
      "    log_feature_importance_plot(features, importance, imp_type)\n",
      "  File \"/home/zarko/.local/lib/python3.9/site-packages/mlflow/xgboost/__init__.py\", line 564, in log_feature_importance_plot\n",
      "    mlflow.log_artifact(filepath)\n",
      "  File \"/home/zarko/.local/lib/python3.9/site-packages/mlflow/tracking/fluent.py\", line 877, in log_artifact\n",
      "    MlflowClient().log_artifact(run_id, local_path, artifact_path)\n",
      "  File \"/home/zarko/.local/lib/python3.9/site-packages/mlflow/tracking/client.py\", line 1091, in log_artifact\n",
      "    self._tracking_client.log_artifact(run_id, local_path, artifact_path)\n",
      "  File \"/home/zarko/.local/lib/python3.9/site-packages/mlflow/tracking/_tracking_service/client.py\", line 448, in log_artifact\n",
      "    artifact_repo = self._get_artifact_repo(run_id)\n",
      "  File \"/home/zarko/.local/lib/python3.9/site-packages/mlflow/tracking/_tracking_service/client.py\", line 433, in _get_artifact_repo\n",
      "    artifact_repo = get_artifact_repository(artifact_uri)\n",
      "  File \"/home/zarko/.local/lib/python3.9/site-packages/mlflow/store/artifact/artifact_repository_registry.py\", line 114, in get_artifact_repository\n",
      "    return _artifact_repository_registry.get_artifact_repository(artifact_uri)\n",
      "  File \"/home/zarko/.local/lib/python3.9/site-packages/mlflow/store/artifact/artifact_repository_registry.py\", line 72, in get_artifact_repository\n",
      "    return repository(artifact_uri)\n",
      "  File \"/home/zarko/.local/lib/python3.9/site-packages/mlflow/store/artifact/mlflow_artifacts_repo.py\", line 45, in __init__\n",
      "    super().__init__(self.resolve_uri(artifact_uri, get_tracking_uri()))\n",
      "  File \"/home/zarko/.local/lib/python3.9/site-packages/mlflow/store/artifact/mlflow_artifacts_repo.py\", line 59, in resolve_uri\n",
      "    _validate_uri_scheme(track_parse.scheme)\n",
      "  File \"/home/zarko/.local/lib/python3.9/site-packages/mlflow/store/artifact/mlflow_artifacts_repo.py\", line 35, in _validate_uri_scheme\n",
      "    raise MlflowException(\n",
      "mlflow.exceptions.MlflowException: The configured tracking uri scheme: 'file' is invalid for use with the proxy mlflow-artifact scheme. The allowed tracking schemes are: {'http', 'https'}\n",
      "2023/07/28 14:27:31 WARNING mlflow.utils.autologging_utils: Encountered unexpected error during xgboost autologging: The configured tracking uri scheme: 'file' is invalid for use with the proxy mlflow-artifact scheme. The allowed tracking schemes are: {'http', 'https'}\n",
      "2023/07/28 14:27:32 WARNING mlflow.utils.autologging_utils: Encountered unexpected error during xgboost autologging: The configured tracking uri scheme: 'file' is invalid for use with the proxy mlflow-artifact scheme. The allowed tracking schemes are: {'http', 'https'}\n",
      "2023/07/28 14:27:34 ERROR mlflow.xgboost: Failed to log feature importance plot. XGBoost autologging will ignore the failure and continue. Exception: \n",
      "Traceback (most recent call last):\n",
      "  File \"/home/zarko/.local/lib/python3.9/site-packages/mlflow/xgboost/__init__.py\", line 665, in train_impl\n",
      "    log_feature_importance_plot(features, importance, imp_type)\n",
      "  File \"/home/zarko/.local/lib/python3.9/site-packages/mlflow/xgboost/__init__.py\", line 564, in log_feature_importance_plot\n",
      "    mlflow.log_artifact(filepath)\n",
      "  File \"/home/zarko/.local/lib/python3.9/site-packages/mlflow/tracking/fluent.py\", line 877, in log_artifact\n",
      "    MlflowClient().log_artifact(run_id, local_path, artifact_path)\n",
      "  File \"/home/zarko/.local/lib/python3.9/site-packages/mlflow/tracking/client.py\", line 1091, in log_artifact\n",
      "    self._tracking_client.log_artifact(run_id, local_path, artifact_path)\n",
      "  File \"/home/zarko/.local/lib/python3.9/site-packages/mlflow/tracking/_tracking_service/client.py\", line 448, in log_artifact\n",
      "    artifact_repo = self._get_artifact_repo(run_id)\n",
      "  File \"/home/zarko/.local/lib/python3.9/site-packages/mlflow/tracking/_tracking_service/client.py\", line 433, in _get_artifact_repo\n",
      "    artifact_repo = get_artifact_repository(artifact_uri)\n",
      "  File \"/home/zarko/.local/lib/python3.9/site-packages/mlflow/store/artifact/artifact_repository_registry.py\", line 114, in get_artifact_repository\n",
      "    return _artifact_repository_registry.get_artifact_repository(artifact_uri)\n",
      "  File \"/home/zarko/.local/lib/python3.9/site-packages/mlflow/store/artifact/artifact_repository_registry.py\", line 72, in get_artifact_repository\n",
      "    return repository(artifact_uri)\n",
      "  File \"/home/zarko/.local/lib/python3.9/site-packages/mlflow/store/artifact/mlflow_artifacts_repo.py\", line 45, in __init__\n",
      "    super().__init__(self.resolve_uri(artifact_uri, get_tracking_uri()))\n",
      "  File \"/home/zarko/.local/lib/python3.9/site-packages/mlflow/store/artifact/mlflow_artifacts_repo.py\", line 59, in resolve_uri\n",
      "    _validate_uri_scheme(track_parse.scheme)\n",
      "  File \"/home/zarko/.local/lib/python3.9/site-packages/mlflow/store/artifact/mlflow_artifacts_repo.py\", line 35, in _validate_uri_scheme\n",
      "    raise MlflowException(\n",
      "mlflow.exceptions.MlflowException: The configured tracking uri scheme: 'file' is invalid for use with the proxy mlflow-artifact scheme. The allowed tracking schemes are: {'http', 'https'}\n",
      "2023/07/28 14:27:34 WARNING mlflow.utils.autologging_utils: Encountered unexpected error during xgboost autologging: The configured tracking uri scheme: 'file' is invalid for use with the proxy mlflow-artifact scheme. The allowed tracking schemes are: {'http', 'https'}\n",
      "2023/07/28 14:27:35 WARNING mlflow.utils.autologging_utils: Encountered unexpected error during xgboost autologging: The configured tracking uri scheme: 'file' is invalid for use with the proxy mlflow-artifact scheme. The allowed tracking schemes are: {'http', 'https'}\n",
      "2023/07/28 14:27:39 ERROR mlflow.xgboost: Failed to log feature importance plot. XGBoost autologging will ignore the failure and continue. Exception: \n",
      "Traceback (most recent call last):\n",
      "  File \"/home/zarko/.local/lib/python3.9/site-packages/mlflow/xgboost/__init__.py\", line 665, in train_impl\n",
      "    log_feature_importance_plot(features, importance, imp_type)\n",
      "  File \"/home/zarko/.local/lib/python3.9/site-packages/mlflow/xgboost/__init__.py\", line 564, in log_feature_importance_plot\n",
      "    mlflow.log_artifact(filepath)\n",
      "  File \"/home/zarko/.local/lib/python3.9/site-packages/mlflow/tracking/fluent.py\", line 877, in log_artifact\n",
      "    MlflowClient().log_artifact(run_id, local_path, artifact_path)\n",
      "  File \"/home/zarko/.local/lib/python3.9/site-packages/mlflow/tracking/client.py\", line 1091, in log_artifact\n",
      "    self._tracking_client.log_artifact(run_id, local_path, artifact_path)\n",
      "  File \"/home/zarko/.local/lib/python3.9/site-packages/mlflow/tracking/_tracking_service/client.py\", line 448, in log_artifact\n",
      "    artifact_repo = self._get_artifact_repo(run_id)\n",
      "  File \"/home/zarko/.local/lib/python3.9/site-packages/mlflow/tracking/_tracking_service/client.py\", line 433, in _get_artifact_repo\n",
      "    artifact_repo = get_artifact_repository(artifact_uri)\n",
      "  File \"/home/zarko/.local/lib/python3.9/site-packages/mlflow/store/artifact/artifact_repository_registry.py\", line 114, in get_artifact_repository\n",
      "    return _artifact_repository_registry.get_artifact_repository(artifact_uri)\n",
      "  File \"/home/zarko/.local/lib/python3.9/site-packages/mlflow/store/artifact/artifact_repository_registry.py\", line 72, in get_artifact_repository\n",
      "    return repository(artifact_uri)\n",
      "  File \"/home/zarko/.local/lib/python3.9/site-packages/mlflow/store/artifact/mlflow_artifacts_repo.py\", line 45, in __init__\n",
      "    super().__init__(self.resolve_uri(artifact_uri, get_tracking_uri()))\n",
      "  File \"/home/zarko/.local/lib/python3.9/site-packages/mlflow/store/artifact/mlflow_artifacts_repo.py\", line 59, in resolve_uri\n",
      "    _validate_uri_scheme(track_parse.scheme)\n",
      "  File \"/home/zarko/.local/lib/python3.9/site-packages/mlflow/store/artifact/mlflow_artifacts_repo.py\", line 35, in _validate_uri_scheme\n",
      "    raise MlflowException(\n",
      "mlflow.exceptions.MlflowException: The configured tracking uri scheme: 'file' is invalid for use with the proxy mlflow-artifact scheme. The allowed tracking schemes are: {'http', 'https'}\n",
      "2023/07/28 14:27:39 WARNING mlflow.utils.autologging_utils: Encountered unexpected error during xgboost autologging: The configured tracking uri scheme: 'file' is invalid for use with the proxy mlflow-artifact scheme. The allowed tracking schemes are: {'http', 'https'}\n",
      "2023/07/28 14:27:40 WARNING mlflow.utils.autologging_utils: Encountered unexpected error during xgboost autologging: The configured tracking uri scheme: 'file' is invalid for use with the proxy mlflow-artifact scheme. The allowed tracking schemes are: {'http', 'https'}\n",
      "2023/07/28 14:27:43 ERROR mlflow.xgboost: Failed to log feature importance plot. XGBoost autologging will ignore the failure and continue. Exception: \n",
      "Traceback (most recent call last):\n",
      "  File \"/home/zarko/.local/lib/python3.9/site-packages/mlflow/xgboost/__init__.py\", line 665, in train_impl\n",
      "    log_feature_importance_plot(features, importance, imp_type)\n",
      "  File \"/home/zarko/.local/lib/python3.9/site-packages/mlflow/xgboost/__init__.py\", line 564, in log_feature_importance_plot\n",
      "    mlflow.log_artifact(filepath)\n",
      "  File \"/home/zarko/.local/lib/python3.9/site-packages/mlflow/tracking/fluent.py\", line 877, in log_artifact\n",
      "    MlflowClient().log_artifact(run_id, local_path, artifact_path)\n",
      "  File \"/home/zarko/.local/lib/python3.9/site-packages/mlflow/tracking/client.py\", line 1091, in log_artifact\n",
      "    self._tracking_client.log_artifact(run_id, local_path, artifact_path)\n",
      "  File \"/home/zarko/.local/lib/python3.9/site-packages/mlflow/tracking/_tracking_service/client.py\", line 448, in log_artifact\n",
      "    artifact_repo = self._get_artifact_repo(run_id)\n",
      "  File \"/home/zarko/.local/lib/python3.9/site-packages/mlflow/tracking/_tracking_service/client.py\", line 433, in _get_artifact_repo\n",
      "    artifact_repo = get_artifact_repository(artifact_uri)\n",
      "  File \"/home/zarko/.local/lib/python3.9/site-packages/mlflow/store/artifact/artifact_repository_registry.py\", line 114, in get_artifact_repository\n",
      "    return _artifact_repository_registry.get_artifact_repository(artifact_uri)\n",
      "  File \"/home/zarko/.local/lib/python3.9/site-packages/mlflow/store/artifact/artifact_repository_registry.py\", line 72, in get_artifact_repository\n",
      "    return repository(artifact_uri)\n",
      "  File \"/home/zarko/.local/lib/python3.9/site-packages/mlflow/store/artifact/mlflow_artifacts_repo.py\", line 45, in __init__\n",
      "    super().__init__(self.resolve_uri(artifact_uri, get_tracking_uri()))\n",
      "  File \"/home/zarko/.local/lib/python3.9/site-packages/mlflow/store/artifact/mlflow_artifacts_repo.py\", line 59, in resolve_uri\n",
      "    _validate_uri_scheme(track_parse.scheme)\n",
      "  File \"/home/zarko/.local/lib/python3.9/site-packages/mlflow/store/artifact/mlflow_artifacts_repo.py\", line 35, in _validate_uri_scheme\n",
      "    raise MlflowException(\n",
      "mlflow.exceptions.MlflowException: The configured tracking uri scheme: 'file' is invalid for use with the proxy mlflow-artifact scheme. The allowed tracking schemes are: {'http', 'https'}\n",
      "2023/07/28 14:27:43 WARNING mlflow.utils.autologging_utils: Encountered unexpected error during xgboost autologging: The configured tracking uri scheme: 'file' is invalid for use with the proxy mlflow-artifact scheme. The allowed tracking schemes are: {'http', 'https'}\n",
      "2023/07/28 14:27:45 WARNING mlflow.utils.autologging_utils: Encountered unexpected error during xgboost autologging: The configured tracking uri scheme: 'file' is invalid for use with the proxy mlflow-artifact scheme. The allowed tracking schemes are: {'http', 'https'}\n",
      "2023/07/28 14:27:48 ERROR mlflow.xgboost: Failed to log feature importance plot. XGBoost autologging will ignore the failure and continue. Exception: \n",
      "Traceback (most recent call last):\n",
      "  File \"/home/zarko/.local/lib/python3.9/site-packages/mlflow/xgboost/__init__.py\", line 665, in train_impl\n",
      "    log_feature_importance_plot(features, importance, imp_type)\n",
      "  File \"/home/zarko/.local/lib/python3.9/site-packages/mlflow/xgboost/__init__.py\", line 564, in log_feature_importance_plot\n",
      "    mlflow.log_artifact(filepath)\n",
      "  File \"/home/zarko/.local/lib/python3.9/site-packages/mlflow/tracking/fluent.py\", line 877, in log_artifact\n",
      "    MlflowClient().log_artifact(run_id, local_path, artifact_path)\n",
      "  File \"/home/zarko/.local/lib/python3.9/site-packages/mlflow/tracking/client.py\", line 1091, in log_artifact\n",
      "    self._tracking_client.log_artifact(run_id, local_path, artifact_path)\n",
      "  File \"/home/zarko/.local/lib/python3.9/site-packages/mlflow/tracking/_tracking_service/client.py\", line 448, in log_artifact\n",
      "    artifact_repo = self._get_artifact_repo(run_id)\n",
      "  File \"/home/zarko/.local/lib/python3.9/site-packages/mlflow/tracking/_tracking_service/client.py\", line 433, in _get_artifact_repo\n",
      "    artifact_repo = get_artifact_repository(artifact_uri)\n",
      "  File \"/home/zarko/.local/lib/python3.9/site-packages/mlflow/store/artifact/artifact_repository_registry.py\", line 114, in get_artifact_repository\n",
      "    return _artifact_repository_registry.get_artifact_repository(artifact_uri)\n",
      "  File \"/home/zarko/.local/lib/python3.9/site-packages/mlflow/store/artifact/artifact_repository_registry.py\", line 72, in get_artifact_repository\n",
      "    return repository(artifact_uri)\n",
      "  File \"/home/zarko/.local/lib/python3.9/site-packages/mlflow/store/artifact/mlflow_artifacts_repo.py\", line 45, in __init__\n",
      "    super().__init__(self.resolve_uri(artifact_uri, get_tracking_uri()))\n",
      "  File \"/home/zarko/.local/lib/python3.9/site-packages/mlflow/store/artifact/mlflow_artifacts_repo.py\", line 59, in resolve_uri\n",
      "    _validate_uri_scheme(track_parse.scheme)\n",
      "  File \"/home/zarko/.local/lib/python3.9/site-packages/mlflow/store/artifact/mlflow_artifacts_repo.py\", line 35, in _validate_uri_scheme\n",
      "    raise MlflowException(\n",
      "mlflow.exceptions.MlflowException: The configured tracking uri scheme: 'file' is invalid for use with the proxy mlflow-artifact scheme. The allowed tracking schemes are: {'http', 'https'}\n",
      "2023/07/28 14:27:48 WARNING mlflow.utils.autologging_utils: Encountered unexpected error during xgboost autologging: The configured tracking uri scheme: 'file' is invalid for use with the proxy mlflow-artifact scheme. The allowed tracking schemes are: {'http', 'https'}\n",
      "2023/07/28 14:27:49 WARNING mlflow.utils.autologging_utils: Encountered unexpected error during xgboost autologging: The configured tracking uri scheme: 'file' is invalid for use with the proxy mlflow-artifact scheme. The allowed tracking schemes are: {'http', 'https'}\n",
      "2023/07/28 14:27:51 ERROR mlflow.xgboost: Failed to log feature importance plot. XGBoost autologging will ignore the failure and continue. Exception: \n",
      "Traceback (most recent call last):\n",
      "  File \"/home/zarko/.local/lib/python3.9/site-packages/mlflow/xgboost/__init__.py\", line 665, in train_impl\n",
      "    log_feature_importance_plot(features, importance, imp_type)\n",
      "  File \"/home/zarko/.local/lib/python3.9/site-packages/mlflow/xgboost/__init__.py\", line 564, in log_feature_importance_plot\n",
      "    mlflow.log_artifact(filepath)\n",
      "  File \"/home/zarko/.local/lib/python3.9/site-packages/mlflow/tracking/fluent.py\", line 877, in log_artifact\n",
      "    MlflowClient().log_artifact(run_id, local_path, artifact_path)\n",
      "  File \"/home/zarko/.local/lib/python3.9/site-packages/mlflow/tracking/client.py\", line 1091, in log_artifact\n",
      "    self._tracking_client.log_artifact(run_id, local_path, artifact_path)\n",
      "  File \"/home/zarko/.local/lib/python3.9/site-packages/mlflow/tracking/_tracking_service/client.py\", line 448, in log_artifact\n",
      "    artifact_repo = self._get_artifact_repo(run_id)\n",
      "  File \"/home/zarko/.local/lib/python3.9/site-packages/mlflow/tracking/_tracking_service/client.py\", line 433, in _get_artifact_repo\n",
      "    artifact_repo = get_artifact_repository(artifact_uri)\n",
      "  File \"/home/zarko/.local/lib/python3.9/site-packages/mlflow/store/artifact/artifact_repository_registry.py\", line 114, in get_artifact_repository\n",
      "    return _artifact_repository_registry.get_artifact_repository(artifact_uri)\n",
      "  File \"/home/zarko/.local/lib/python3.9/site-packages/mlflow/store/artifact/artifact_repository_registry.py\", line 72, in get_artifact_repository\n",
      "    return repository(artifact_uri)\n",
      "  File \"/home/zarko/.local/lib/python3.9/site-packages/mlflow/store/artifact/mlflow_artifacts_repo.py\", line 45, in __init__\n",
      "    super().__init__(self.resolve_uri(artifact_uri, get_tracking_uri()))\n",
      "  File \"/home/zarko/.local/lib/python3.9/site-packages/mlflow/store/artifact/mlflow_artifacts_repo.py\", line 59, in resolve_uri\n",
      "    _validate_uri_scheme(track_parse.scheme)\n",
      "  File \"/home/zarko/.local/lib/python3.9/site-packages/mlflow/store/artifact/mlflow_artifacts_repo.py\", line 35, in _validate_uri_scheme\n",
      "    raise MlflowException(\n",
      "mlflow.exceptions.MlflowException: The configured tracking uri scheme: 'file' is invalid for use with the proxy mlflow-artifact scheme. The allowed tracking schemes are: {'http', 'https'}\n",
      "2023/07/28 14:27:51 WARNING mlflow.utils.autologging_utils: Encountered unexpected error during xgboost autologging: The configured tracking uri scheme: 'file' is invalid for use with the proxy mlflow-artifact scheme. The allowed tracking schemes are: {'http', 'https'}\n",
      "2023/07/28 14:27:53 WARNING mlflow.utils.autologging_utils: Encountered unexpected error during xgboost autologging: The configured tracking uri scheme: 'file' is invalid for use with the proxy mlflow-artifact scheme. The allowed tracking schemes are: {'http', 'https'}\n",
      "2023/07/28 14:27:55 ERROR mlflow.xgboost: Failed to log feature importance plot. XGBoost autologging will ignore the failure and continue. Exception: \n",
      "Traceback (most recent call last):\n",
      "  File \"/home/zarko/.local/lib/python3.9/site-packages/mlflow/xgboost/__init__.py\", line 665, in train_impl\n",
      "    log_feature_importance_plot(features, importance, imp_type)\n",
      "  File \"/home/zarko/.local/lib/python3.9/site-packages/mlflow/xgboost/__init__.py\", line 564, in log_feature_importance_plot\n",
      "    mlflow.log_artifact(filepath)\n",
      "  File \"/home/zarko/.local/lib/python3.9/site-packages/mlflow/tracking/fluent.py\", line 877, in log_artifact\n",
      "    MlflowClient().log_artifact(run_id, local_path, artifact_path)\n",
      "  File \"/home/zarko/.local/lib/python3.9/site-packages/mlflow/tracking/client.py\", line 1091, in log_artifact\n",
      "    self._tracking_client.log_artifact(run_id, local_path, artifact_path)\n",
      "  File \"/home/zarko/.local/lib/python3.9/site-packages/mlflow/tracking/_tracking_service/client.py\", line 448, in log_artifact\n",
      "    artifact_repo = self._get_artifact_repo(run_id)\n",
      "  File \"/home/zarko/.local/lib/python3.9/site-packages/mlflow/tracking/_tracking_service/client.py\", line 433, in _get_artifact_repo\n",
      "    artifact_repo = get_artifact_repository(artifact_uri)\n",
      "  File \"/home/zarko/.local/lib/python3.9/site-packages/mlflow/store/artifact/artifact_repository_registry.py\", line 114, in get_artifact_repository\n",
      "    return _artifact_repository_registry.get_artifact_repository(artifact_uri)\n",
      "  File \"/home/zarko/.local/lib/python3.9/site-packages/mlflow/store/artifact/artifact_repository_registry.py\", line 72, in get_artifact_repository\n",
      "    return repository(artifact_uri)\n",
      "  File \"/home/zarko/.local/lib/python3.9/site-packages/mlflow/store/artifact/mlflow_artifacts_repo.py\", line 45, in __init__\n",
      "    super().__init__(self.resolve_uri(artifact_uri, get_tracking_uri()))\n",
      "  File \"/home/zarko/.local/lib/python3.9/site-packages/mlflow/store/artifact/mlflow_artifacts_repo.py\", line 59, in resolve_uri\n",
      "    _validate_uri_scheme(track_parse.scheme)\n",
      "  File \"/home/zarko/.local/lib/python3.9/site-packages/mlflow/store/artifact/mlflow_artifacts_repo.py\", line 35, in _validate_uri_scheme\n",
      "    raise MlflowException(\n",
      "mlflow.exceptions.MlflowException: The configured tracking uri scheme: 'file' is invalid for use with the proxy mlflow-artifact scheme. The allowed tracking schemes are: {'http', 'https'}\n",
      "2023/07/28 14:27:55 WARNING mlflow.utils.autologging_utils: Encountered unexpected error during xgboost autologging: The configured tracking uri scheme: 'file' is invalid for use with the proxy mlflow-artifact scheme. The allowed tracking schemes are: {'http', 'https'}\n",
      "2023/07/28 14:27:57 WARNING mlflow.utils.autologging_utils: Encountered unexpected error during xgboost autologging: The configured tracking uri scheme: 'file' is invalid for use with the proxy mlflow-artifact scheme. The allowed tracking schemes are: {'http', 'https'}\n",
      "2023/07/28 14:27:59 ERROR mlflow.xgboost: Failed to log feature importance plot. XGBoost autologging will ignore the failure and continue. Exception: \n",
      "Traceback (most recent call last):\n",
      "  File \"/home/zarko/.local/lib/python3.9/site-packages/mlflow/xgboost/__init__.py\", line 665, in train_impl\n",
      "    log_feature_importance_plot(features, importance, imp_type)\n",
      "  File \"/home/zarko/.local/lib/python3.9/site-packages/mlflow/xgboost/__init__.py\", line 564, in log_feature_importance_plot\n",
      "    mlflow.log_artifact(filepath)\n",
      "  File \"/home/zarko/.local/lib/python3.9/site-packages/mlflow/tracking/fluent.py\", line 877, in log_artifact\n",
      "    MlflowClient().log_artifact(run_id, local_path, artifact_path)\n",
      "  File \"/home/zarko/.local/lib/python3.9/site-packages/mlflow/tracking/client.py\", line 1091, in log_artifact\n",
      "    self._tracking_client.log_artifact(run_id, local_path, artifact_path)\n",
      "  File \"/home/zarko/.local/lib/python3.9/site-packages/mlflow/tracking/_tracking_service/client.py\", line 448, in log_artifact\n",
      "    artifact_repo = self._get_artifact_repo(run_id)\n",
      "  File \"/home/zarko/.local/lib/python3.9/site-packages/mlflow/tracking/_tracking_service/client.py\", line 433, in _get_artifact_repo\n",
      "    artifact_repo = get_artifact_repository(artifact_uri)\n",
      "  File \"/home/zarko/.local/lib/python3.9/site-packages/mlflow/store/artifact/artifact_repository_registry.py\", line 114, in get_artifact_repository\n",
      "    return _artifact_repository_registry.get_artifact_repository(artifact_uri)\n",
      "  File \"/home/zarko/.local/lib/python3.9/site-packages/mlflow/store/artifact/artifact_repository_registry.py\", line 72, in get_artifact_repository\n",
      "    return repository(artifact_uri)\n",
      "  File \"/home/zarko/.local/lib/python3.9/site-packages/mlflow/store/artifact/mlflow_artifacts_repo.py\", line 45, in __init__\n",
      "    super().__init__(self.resolve_uri(artifact_uri, get_tracking_uri()))\n",
      "  File \"/home/zarko/.local/lib/python3.9/site-packages/mlflow/store/artifact/mlflow_artifacts_repo.py\", line 59, in resolve_uri\n",
      "    _validate_uri_scheme(track_parse.scheme)\n",
      "  File \"/home/zarko/.local/lib/python3.9/site-packages/mlflow/store/artifact/mlflow_artifacts_repo.py\", line 35, in _validate_uri_scheme\n",
      "    raise MlflowException(\n",
      "mlflow.exceptions.MlflowException: The configured tracking uri scheme: 'file' is invalid for use with the proxy mlflow-artifact scheme. The allowed tracking schemes are: {'http', 'https'}\n",
      "2023/07/28 14:28:00 WARNING mlflow.utils.autologging_utils: Encountered unexpected error during xgboost autologging: The configured tracking uri scheme: 'file' is invalid for use with the proxy mlflow-artifact scheme. The allowed tracking schemes are: {'http', 'https'}\n",
      "2023/07/28 14:28:01 WARNING mlflow.utils.autologging_utils: Encountered unexpected error during xgboost autologging: The configured tracking uri scheme: 'file' is invalid for use with the proxy mlflow-artifact scheme. The allowed tracking schemes are: {'http', 'https'}\n",
      "2023/07/28 14:28:03 ERROR mlflow.xgboost: Failed to log feature importance plot. XGBoost autologging will ignore the failure and continue. Exception: \n",
      "Traceback (most recent call last):\n",
      "  File \"/home/zarko/.local/lib/python3.9/site-packages/mlflow/xgboost/__init__.py\", line 665, in train_impl\n",
      "    log_feature_importance_plot(features, importance, imp_type)\n",
      "  File \"/home/zarko/.local/lib/python3.9/site-packages/mlflow/xgboost/__init__.py\", line 564, in log_feature_importance_plot\n",
      "    mlflow.log_artifact(filepath)\n",
      "  File \"/home/zarko/.local/lib/python3.9/site-packages/mlflow/tracking/fluent.py\", line 877, in log_artifact\n",
      "    MlflowClient().log_artifact(run_id, local_path, artifact_path)\n",
      "  File \"/home/zarko/.local/lib/python3.9/site-packages/mlflow/tracking/client.py\", line 1091, in log_artifact\n",
      "    self._tracking_client.log_artifact(run_id, local_path, artifact_path)\n",
      "  File \"/home/zarko/.local/lib/python3.9/site-packages/mlflow/tracking/_tracking_service/client.py\", line 448, in log_artifact\n",
      "    artifact_repo = self._get_artifact_repo(run_id)\n",
      "  File \"/home/zarko/.local/lib/python3.9/site-packages/mlflow/tracking/_tracking_service/client.py\", line 433, in _get_artifact_repo\n",
      "    artifact_repo = get_artifact_repository(artifact_uri)\n",
      "  File \"/home/zarko/.local/lib/python3.9/site-packages/mlflow/store/artifact/artifact_repository_registry.py\", line 114, in get_artifact_repository\n",
      "    return _artifact_repository_registry.get_artifact_repository(artifact_uri)\n",
      "  File \"/home/zarko/.local/lib/python3.9/site-packages/mlflow/store/artifact/artifact_repository_registry.py\", line 72, in get_artifact_repository\n",
      "    return repository(artifact_uri)\n",
      "  File \"/home/zarko/.local/lib/python3.9/site-packages/mlflow/store/artifact/mlflow_artifacts_repo.py\", line 45, in __init__\n",
      "    super().__init__(self.resolve_uri(artifact_uri, get_tracking_uri()))\n",
      "  File \"/home/zarko/.local/lib/python3.9/site-packages/mlflow/store/artifact/mlflow_artifacts_repo.py\", line 59, in resolve_uri\n",
      "    _validate_uri_scheme(track_parse.scheme)\n",
      "  File \"/home/zarko/.local/lib/python3.9/site-packages/mlflow/store/artifact/mlflow_artifacts_repo.py\", line 35, in _validate_uri_scheme\n",
      "    raise MlflowException(\n",
      "mlflow.exceptions.MlflowException: The configured tracking uri scheme: 'file' is invalid for use with the proxy mlflow-artifact scheme. The allowed tracking schemes are: {'http', 'https'}\n",
      "2023/07/28 14:28:03 WARNING mlflow.utils.autologging_utils: Encountered unexpected error during xgboost autologging: The configured tracking uri scheme: 'file' is invalid for use with the proxy mlflow-artifact scheme. The allowed tracking schemes are: {'http', 'https'}\n",
      "2023/07/28 14:28:04 WARNING mlflow.utils.autologging_utils: Encountered unexpected error during xgboost autologging: The configured tracking uri scheme: 'file' is invalid for use with the proxy mlflow-artifact scheme. The allowed tracking schemes are: {'http', 'https'}\n",
      "2023/07/28 14:28:08 ERROR mlflow.xgboost: Failed to log feature importance plot. XGBoost autologging will ignore the failure and continue. Exception: \n",
      "Traceback (most recent call last):\n",
      "  File \"/home/zarko/.local/lib/python3.9/site-packages/mlflow/xgboost/__init__.py\", line 665, in train_impl\n",
      "    log_feature_importance_plot(features, importance, imp_type)\n",
      "  File \"/home/zarko/.local/lib/python3.9/site-packages/mlflow/xgboost/__init__.py\", line 564, in log_feature_importance_plot\n",
      "    mlflow.log_artifact(filepath)\n",
      "  File \"/home/zarko/.local/lib/python3.9/site-packages/mlflow/tracking/fluent.py\", line 877, in log_artifact\n",
      "    MlflowClient().log_artifact(run_id, local_path, artifact_path)\n",
      "  File \"/home/zarko/.local/lib/python3.9/site-packages/mlflow/tracking/client.py\", line 1091, in log_artifact\n",
      "    self._tracking_client.log_artifact(run_id, local_path, artifact_path)\n",
      "  File \"/home/zarko/.local/lib/python3.9/site-packages/mlflow/tracking/_tracking_service/client.py\", line 448, in log_artifact\n",
      "    artifact_repo = self._get_artifact_repo(run_id)\n",
      "  File \"/home/zarko/.local/lib/python3.9/site-packages/mlflow/tracking/_tracking_service/client.py\", line 433, in _get_artifact_repo\n",
      "    artifact_repo = get_artifact_repository(artifact_uri)\n",
      "  File \"/home/zarko/.local/lib/python3.9/site-packages/mlflow/store/artifact/artifact_repository_registry.py\", line 114, in get_artifact_repository\n",
      "    return _artifact_repository_registry.get_artifact_repository(artifact_uri)\n",
      "  File \"/home/zarko/.local/lib/python3.9/site-packages/mlflow/store/artifact/artifact_repository_registry.py\", line 72, in get_artifact_repository\n",
      "    return repository(artifact_uri)\n",
      "  File \"/home/zarko/.local/lib/python3.9/site-packages/mlflow/store/artifact/mlflow_artifacts_repo.py\", line 45, in __init__\n",
      "    super().__init__(self.resolve_uri(artifact_uri, get_tracking_uri()))\n",
      "  File \"/home/zarko/.local/lib/python3.9/site-packages/mlflow/store/artifact/mlflow_artifacts_repo.py\", line 59, in resolve_uri\n",
      "    _validate_uri_scheme(track_parse.scheme)\n",
      "  File \"/home/zarko/.local/lib/python3.9/site-packages/mlflow/store/artifact/mlflow_artifacts_repo.py\", line 35, in _validate_uri_scheme\n",
      "    raise MlflowException(\n",
      "mlflow.exceptions.MlflowException: The configured tracking uri scheme: 'file' is invalid for use with the proxy mlflow-artifact scheme. The allowed tracking schemes are: {'http', 'https'}\n",
      "2023/07/28 14:28:08 WARNING mlflow.utils.autologging_utils: Encountered unexpected error during xgboost autologging: The configured tracking uri scheme: 'file' is invalid for use with the proxy mlflow-artifact scheme. The allowed tracking schemes are: {'http', 'https'}\n",
      "2023/07/28 14:28:10 WARNING mlflow.utils.autologging_utils: Encountered unexpected error during xgboost autologging: The configured tracking uri scheme: 'file' is invalid for use with the proxy mlflow-artifact scheme. The allowed tracking schemes are: {'http', 'https'}\n",
      "2023/07/28 14:28:13 ERROR mlflow.xgboost: Failed to log feature importance plot. XGBoost autologging will ignore the failure and continue. Exception: \n",
      "Traceback (most recent call last):\n",
      "  File \"/home/zarko/.local/lib/python3.9/site-packages/mlflow/xgboost/__init__.py\", line 665, in train_impl\n",
      "    log_feature_importance_plot(features, importance, imp_type)\n",
      "  File \"/home/zarko/.local/lib/python3.9/site-packages/mlflow/xgboost/__init__.py\", line 564, in log_feature_importance_plot\n",
      "    mlflow.log_artifact(filepath)\n",
      "  File \"/home/zarko/.local/lib/python3.9/site-packages/mlflow/tracking/fluent.py\", line 877, in log_artifact\n",
      "    MlflowClient().log_artifact(run_id, local_path, artifact_path)\n",
      "  File \"/home/zarko/.local/lib/python3.9/site-packages/mlflow/tracking/client.py\", line 1091, in log_artifact\n",
      "    self._tracking_client.log_artifact(run_id, local_path, artifact_path)\n",
      "  File \"/home/zarko/.local/lib/python3.9/site-packages/mlflow/tracking/_tracking_service/client.py\", line 448, in log_artifact\n",
      "    artifact_repo = self._get_artifact_repo(run_id)\n",
      "  File \"/home/zarko/.local/lib/python3.9/site-packages/mlflow/tracking/_tracking_service/client.py\", line 433, in _get_artifact_repo\n",
      "    artifact_repo = get_artifact_repository(artifact_uri)\n",
      "  File \"/home/zarko/.local/lib/python3.9/site-packages/mlflow/store/artifact/artifact_repository_registry.py\", line 114, in get_artifact_repository\n",
      "    return _artifact_repository_registry.get_artifact_repository(artifact_uri)\n",
      "  File \"/home/zarko/.local/lib/python3.9/site-packages/mlflow/store/artifact/artifact_repository_registry.py\", line 72, in get_artifact_repository\n",
      "    return repository(artifact_uri)\n",
      "  File \"/home/zarko/.local/lib/python3.9/site-packages/mlflow/store/artifact/mlflow_artifacts_repo.py\", line 45, in __init__\n",
      "    super().__init__(self.resolve_uri(artifact_uri, get_tracking_uri()))\n",
      "  File \"/home/zarko/.local/lib/python3.9/site-packages/mlflow/store/artifact/mlflow_artifacts_repo.py\", line 59, in resolve_uri\n",
      "    _validate_uri_scheme(track_parse.scheme)\n",
      "  File \"/home/zarko/.local/lib/python3.9/site-packages/mlflow/store/artifact/mlflow_artifacts_repo.py\", line 35, in _validate_uri_scheme\n",
      "    raise MlflowException(\n",
      "mlflow.exceptions.MlflowException: The configured tracking uri scheme: 'file' is invalid for use with the proxy mlflow-artifact scheme. The allowed tracking schemes are: {'http', 'https'}\n",
      "2023/07/28 14:28:13 WARNING mlflow.utils.autologging_utils: Encountered unexpected error during xgboost autologging: The configured tracking uri scheme: 'file' is invalid for use with the proxy mlflow-artifact scheme. The allowed tracking schemes are: {'http', 'https'}\n",
      "2023/07/28 14:28:15 WARNING mlflow.utils.autologging_utils: Encountered unexpected error during xgboost autologging: The configured tracking uri scheme: 'file' is invalid for use with the proxy mlflow-artifact scheme. The allowed tracking schemes are: {'http', 'https'}\n"
     ]
    },
    {
     "name": "stdout",
     "output_type": "stream",
     "text": [
      "0.4223602484472049 0.09316770186335394\n",
      "0.40391078617794685 0.06912300149885775\n",
      "max acc: 0.4658385093167702\n",
      "min acc: 0.32919254658385094\n",
      "avg precision 0.41556337879717536\n",
      "min precision: 0.3288865019692087\n",
      "max precision: 0.48693241943241944\n",
      "avg recall: 0.41003893349478127\n",
      "min recall: 0.3567667299477931\n",
      "max recall: 0.4627685013399299\n",
      "\n",
      " Matrica konfuzije za max tacnost: 0.4658385093167702\n"
     ]
    }
   ],
   "source": [
    "acc =  []\n",
    "f1 =   []\n",
    "acct = []\n",
    "prec = []\n",
    "recall =   []\n",
    "conf_mat = []\n",
    "\n",
    "k = 20\n",
    "for i in range(k):\n",
    "    X_train, X_test, y_train, y_test = train_test_split(X, y, test_size=0.3)\n",
    "    xgb = XGBClassifier(objective='multiclass:softmax', learning_rate = 0.311,max_depth = 3, n_estimators = 500)\n",
    "    xgb.fit(X_train, y_train)\n",
    "    \n",
    "    test_preds = xgb.predict(X_test)\n",
    "    train_preds = xgb.predict(X_train)\n",
    "\n",
    "\n",
    "    y_test = list(y_test)\n",
    "    metrics = get_metrics(y_test, test_preds)\n",
    "\n",
    "\n",
    "\n",
    "    acc.append(metrics['accuracy'])\n",
    "    f1.append(metrics['f1'])\n",
    "    prec.append(metrics['precision'])\n",
    "    recall.append(metrics['recall'])\n",
    "    # conf_mat.append(metrics['confusion_matrix'])\n",
    "\n",
    "    y_train = list(y_train)\n",
    "\n",
    "\n",
    "\n",
    "    dataset = mlflow.data.from_numpy(X_test)\n",
    "    mlflow.log_input(dataset, context=\"testing\")\n",
    "    mlflow.log_metrics(metrics)\n",
    "\n",
    "    m1 = get_metrics(y_train, train_preds)\n",
    "    acct.append(m1['accuracy'])\n",
    "\n",
    "\n",
    "mlflow.end_run()\n",
    "\n",
    "\n",
    "acc_sr = sum(acc)/len(acc)\n",
    "f1_sr =  sum(f1)/len(f1)\n",
    "acc_std = max(max(acc)-acc_sr, acc_sr-min(acc))\n",
    "f1_std = max(max(f1)-f1_sr, f1_sr-min(f1))\n",
    "\n",
    "print(acc_sr, acc_std)\n",
    "print(f1_sr, f1_std)\n",
    "print(\"max acc:\", max(acc))\n",
    "print(\"min acc:\", min(acc))\n",
    "print(\"avg precision\", sum(prec)/len(prec))\n",
    "print(\"min precision:\", min(prec) )\n",
    "print(\"max precision:\", max(prec) )\n",
    "print(\"avg recall:\", sum(recall)/len(recall))\n",
    "print(\"min recall:\",    min(recall) )\n",
    "print(\"max recall:\",    max(recall) )\n",
    "\n",
    "print(\"\\n Matrica konfuzije za max tacnost:\", max(acc))"
   ]
  },
  {
   "cell_type": "code",
   "execution_count": 6,
   "metadata": {},
   "outputs": [
    {
     "name": "stdout",
     "output_type": "stream",
     "text": [
      "0.5900621118012422\n"
     ]
    }
   ],
   "source": [
    "test_acc = accuracy_score(y_test, test_preds)\n",
    "print(test_acc)"
   ]
  },
  {
   "cell_type": "code",
   "execution_count": 7,
   "metadata": {},
   "outputs": [
    {
     "name": "stdout",
     "output_type": "stream",
     "text": [
      "1.0\n"
     ]
    }
   ],
   "source": [
    "train_acc = accuracy_score(y_train, train_preds)\n",
    "print(train_acc)"
   ]
  },
  {
   "cell_type": "code",
   "execution_count": 8,
   "metadata": {},
   "outputs": [
    {
     "name": "stderr",
     "output_type": "stream",
     "text": [
      "/home/zarko/.local/lib/python3.9/site-packages/sklearn/model_selection/_split.py:680: UserWarning: The least populated class in y has only 12 members, which is less than n_splits=20.\n",
      "  warnings.warn(\n",
      "2023/07/27 21:41:12 INFO mlflow.utils.autologging_utils: Created MLflow autologging run with ID '2e921fb73222413790607619ad849072', which will track hyperparameters, performance metrics, model artifacts, and lineage information for the current xgboost workflow\n",
      "2023/07/27 21:41:15 WARNING mlflow.models.model: Logging model metadata to the tracking server has failed. The model artifacts have been logged successfully under /home/zarko/PFE/prepoznavanje-emocija/lk-s-2023-prepoznavanje-emocija/mlruns/0/2e921fb73222413790607619ad849072/artifacts. Set logging level to DEBUG via `logging.getLogger(\"mlflow\").setLevel(logging.DEBUG)` to see the full traceback.\n",
      "2023/07/27 21:41:15 INFO mlflow.utils.autologging_utils: Created MLflow autologging run with ID 'b54bc1dd18054db7ae8aab4db1769d38', which will track hyperparameters, performance metrics, model artifacts, and lineage information for the current xgboost workflow\n",
      "2023/07/27 21:41:20 WARNING mlflow.models.model: Logging model metadata to the tracking server has failed. The model artifacts have been logged successfully under /home/zarko/PFE/prepoznavanje-emocija/lk-s-2023-prepoznavanje-emocija/mlruns/0/b54bc1dd18054db7ae8aab4db1769d38/artifacts. Set logging level to DEBUG via `logging.getLogger(\"mlflow\").setLevel(logging.DEBUG)` to see the full traceback.\n",
      "2023/07/27 21:41:20 INFO mlflow.utils.autologging_utils: Created MLflow autologging run with ID '09e4d8763a84466fbd5b831e6743b42c', which will track hyperparameters, performance metrics, model artifacts, and lineage information for the current xgboost workflow\n",
      "2023/07/27 21:41:23 WARNING mlflow.models.model: Logging model metadata to the tracking server has failed. The model artifacts have been logged successfully under /home/zarko/PFE/prepoznavanje-emocija/lk-s-2023-prepoznavanje-emocija/mlruns/0/09e4d8763a84466fbd5b831e6743b42c/artifacts. Set logging level to DEBUG via `logging.getLogger(\"mlflow\").setLevel(logging.DEBUG)` to see the full traceback.\n",
      "2023/07/27 21:41:23 INFO mlflow.utils.autologging_utils: Created MLflow autologging run with ID '4bd73f0ee77a42be9094ddae980d4099', which will track hyperparameters, performance metrics, model artifacts, and lineage information for the current xgboost workflow\n",
      "2023/07/27 21:41:26 WARNING mlflow.models.model: Logging model metadata to the tracking server has failed. The model artifacts have been logged successfully under /home/zarko/PFE/prepoznavanje-emocija/lk-s-2023-prepoznavanje-emocija/mlruns/0/4bd73f0ee77a42be9094ddae980d4099/artifacts. Set logging level to DEBUG via `logging.getLogger(\"mlflow\").setLevel(logging.DEBUG)` to see the full traceback.\n",
      "2023/07/27 21:41:26 INFO mlflow.utils.autologging_utils: Created MLflow autologging run with ID 'a432c70e56e34694b4fe596628aad862', which will track hyperparameters, performance metrics, model artifacts, and lineage information for the current xgboost workflow\n",
      "2023/07/27 21:41:30 WARNING mlflow.models.model: Logging model metadata to the tracking server has failed. The model artifacts have been logged successfully under /home/zarko/PFE/prepoznavanje-emocija/lk-s-2023-prepoznavanje-emocija/mlruns/0/a432c70e56e34694b4fe596628aad862/artifacts. Set logging level to DEBUG via `logging.getLogger(\"mlflow\").setLevel(logging.DEBUG)` to see the full traceback.\n",
      "2023/07/27 21:41:30 INFO mlflow.utils.autologging_utils: Created MLflow autologging run with ID '7697df3e62af44bd9b062179378ed4d3', which will track hyperparameters, performance metrics, model artifacts, and lineage information for the current xgboost workflow\n",
      "2023/07/27 21:41:33 WARNING mlflow.models.model: Logging model metadata to the tracking server has failed. The model artifacts have been logged successfully under /home/zarko/PFE/prepoznavanje-emocija/lk-s-2023-prepoznavanje-emocija/mlruns/0/7697df3e62af44bd9b062179378ed4d3/artifacts. Set logging level to DEBUG via `logging.getLogger(\"mlflow\").setLevel(logging.DEBUG)` to see the full traceback.\n",
      "2023/07/27 21:41:33 INFO mlflow.utils.autologging_utils: Created MLflow autologging run with ID 'a3a385041f1149a98ee3d8a302637f37', which will track hyperparameters, performance metrics, model artifacts, and lineage information for the current xgboost workflow\n",
      "2023/07/27 21:41:37 WARNING mlflow.models.model: Logging model metadata to the tracking server has failed. The model artifacts have been logged successfully under /home/zarko/PFE/prepoznavanje-emocija/lk-s-2023-prepoznavanje-emocija/mlruns/0/a3a385041f1149a98ee3d8a302637f37/artifacts. Set logging level to DEBUG via `logging.getLogger(\"mlflow\").setLevel(logging.DEBUG)` to see the full traceback.\n",
      "2023/07/27 21:41:37 INFO mlflow.utils.autologging_utils: Created MLflow autologging run with ID '0e66785c477d4c1ab52901e1cd96718e', which will track hyperparameters, performance metrics, model artifacts, and lineage information for the current xgboost workflow\n",
      "2023/07/27 21:41:56 WARNING mlflow.models.model: Logging model metadata to the tracking server has failed. The model artifacts have been logged successfully under /home/zarko/PFE/prepoznavanje-emocija/lk-s-2023-prepoznavanje-emocija/mlruns/0/0e66785c477d4c1ab52901e1cd96718e/artifacts. Set logging level to DEBUG via `logging.getLogger(\"mlflow\").setLevel(logging.DEBUG)` to see the full traceback.\n",
      "2023/07/27 21:41:56 INFO mlflow.utils.autologging_utils: Created MLflow autologging run with ID '57a8470350e444bd98f53315b2d741c1', which will track hyperparameters, performance metrics, model artifacts, and lineage information for the current xgboost workflow\n",
      "2023/07/27 21:42:31 WARNING mlflow.models.model: Logging model metadata to the tracking server has failed. The model artifacts have been logged successfully under /home/zarko/PFE/prepoznavanje-emocija/lk-s-2023-prepoznavanje-emocija/mlruns/0/57a8470350e444bd98f53315b2d741c1/artifacts. Set logging level to DEBUG via `logging.getLogger(\"mlflow\").setLevel(logging.DEBUG)` to see the full traceback.\n",
      "2023/07/27 21:42:32 INFO mlflow.utils.autologging_utils: Created MLflow autologging run with ID '518a05c98e6c430d8818802a045dc747', which will track hyperparameters, performance metrics, model artifacts, and lineage information for the current xgboost workflow\n",
      "2023/07/27 21:43:06 WARNING mlflow.models.model: Logging model metadata to the tracking server has failed. The model artifacts have been logged successfully under /home/zarko/PFE/prepoznavanje-emocija/lk-s-2023-prepoznavanje-emocija/mlruns/0/518a05c98e6c430d8818802a045dc747/artifacts. Set logging level to DEBUG via `logging.getLogger(\"mlflow\").setLevel(logging.DEBUG)` to see the full traceback.\n",
      "2023/07/27 21:43:06 INFO mlflow.utils.autologging_utils: Created MLflow autologging run with ID 'c7985caa517c49a5a08bbf533e5cb7d8', which will track hyperparameters, performance metrics, model artifacts, and lineage information for the current xgboost workflow\n",
      "2023/07/27 21:43:08 WARNING mlflow.models.model: Logging model metadata to the tracking server has failed. The model artifacts have been logged successfully under /home/zarko/PFE/prepoznavanje-emocija/lk-s-2023-prepoznavanje-emocija/mlruns/0/c7985caa517c49a5a08bbf533e5cb7d8/artifacts. Set logging level to DEBUG via `logging.getLogger(\"mlflow\").setLevel(logging.DEBUG)` to see the full traceback.\n",
      "2023/07/27 21:43:08 INFO mlflow.utils.autologging_utils: Created MLflow autologging run with ID '32fb9a44078e4b44825e252f8a861561', which will track hyperparameters, performance metrics, model artifacts, and lineage information for the current xgboost workflow\n",
      "2023/07/27 21:43:11 WARNING mlflow.models.model: Logging model metadata to the tracking server has failed. The model artifacts have been logged successfully under /home/zarko/PFE/prepoznavanje-emocija/lk-s-2023-prepoznavanje-emocija/mlruns/0/32fb9a44078e4b44825e252f8a861561/artifacts. Set logging level to DEBUG via `logging.getLogger(\"mlflow\").setLevel(logging.DEBUG)` to see the full traceback.\n",
      "2023/07/27 21:43:11 INFO mlflow.utils.autologging_utils: Created MLflow autologging run with ID '4d4d813dfd774a7395aa3485ccb11dd5', which will track hyperparameters, performance metrics, model artifacts, and lineage information for the current xgboost workflow\n",
      "2023/07/27 21:43:14 WARNING mlflow.models.model: Logging model metadata to the tracking server has failed. The model artifacts have been logged successfully under /home/zarko/PFE/prepoznavanje-emocija/lk-s-2023-prepoznavanje-emocija/mlruns/0/4d4d813dfd774a7395aa3485ccb11dd5/artifacts. Set logging level to DEBUG via `logging.getLogger(\"mlflow\").setLevel(logging.DEBUG)` to see the full traceback.\n",
      "2023/07/27 21:43:14 INFO mlflow.utils.autologging_utils: Created MLflow autologging run with ID '025433ff7f6f46e0b9cf28a2a678e0cf', which will track hyperparameters, performance metrics, model artifacts, and lineage information for the current xgboost workflow\n",
      "2023/07/27 21:43:17 WARNING mlflow.models.model: Logging model metadata to the tracking server has failed. The model artifacts have been logged successfully under /home/zarko/PFE/prepoznavanje-emocija/lk-s-2023-prepoznavanje-emocija/mlruns/0/025433ff7f6f46e0b9cf28a2a678e0cf/artifacts. Set logging level to DEBUG via `logging.getLogger(\"mlflow\").setLevel(logging.DEBUG)` to see the full traceback.\n",
      "2023/07/27 21:43:17 INFO mlflow.utils.autologging_utils: Created MLflow autologging run with ID 'e029d7d9dead41999b3c0513e40a19cd', which will track hyperparameters, performance metrics, model artifacts, and lineage information for the current xgboost workflow\n",
      "2023/07/27 21:43:20 WARNING mlflow.models.model: Logging model metadata to the tracking server has failed. The model artifacts have been logged successfully under /home/zarko/PFE/prepoznavanje-emocija/lk-s-2023-prepoznavanje-emocija/mlruns/0/e029d7d9dead41999b3c0513e40a19cd/artifacts. Set logging level to DEBUG via `logging.getLogger(\"mlflow\").setLevel(logging.DEBUG)` to see the full traceback.\n",
      "2023/07/27 21:43:20 INFO mlflow.utils.autologging_utils: Created MLflow autologging run with ID '6460fbc5a31640d1857cfd4ea5eb50d3', which will track hyperparameters, performance metrics, model artifacts, and lineage information for the current xgboost workflow\n",
      "2023/07/27 21:43:23 WARNING mlflow.models.model: Logging model metadata to the tracking server has failed. The model artifacts have been logged successfully under /home/zarko/PFE/prepoznavanje-emocija/lk-s-2023-prepoznavanje-emocija/mlruns/0/6460fbc5a31640d1857cfd4ea5eb50d3/artifacts. Set logging level to DEBUG via `logging.getLogger(\"mlflow\").setLevel(logging.DEBUG)` to see the full traceback.\n",
      "2023/07/27 21:43:23 INFO mlflow.utils.autologging_utils: Created MLflow autologging run with ID '755fd73b9c4f4a3fb8db16e8bdf21ba1', which will track hyperparameters, performance metrics, model artifacts, and lineage information for the current xgboost workflow\n",
      "2023/07/27 21:43:26 WARNING mlflow.models.model: Logging model metadata to the tracking server has failed. The model artifacts have been logged successfully under /home/zarko/PFE/prepoznavanje-emocija/lk-s-2023-prepoznavanje-emocija/mlruns/0/755fd73b9c4f4a3fb8db16e8bdf21ba1/artifacts. Set logging level to DEBUG via `logging.getLogger(\"mlflow\").setLevel(logging.DEBUG)` to see the full traceback.\n",
      "2023/07/27 21:43:26 INFO mlflow.utils.autologging_utils: Created MLflow autologging run with ID '7894666a2b7642f2a73c78ce751ae2e0', which will track hyperparameters, performance metrics, model artifacts, and lineage information for the current xgboost workflow\n",
      "2023/07/27 21:43:29 WARNING mlflow.models.model: Logging model metadata to the tracking server has failed. The model artifacts have been logged successfully under /home/zarko/PFE/prepoznavanje-emocija/lk-s-2023-prepoznavanje-emocija/mlruns/0/7894666a2b7642f2a73c78ce751ae2e0/artifacts. Set logging level to DEBUG via `logging.getLogger(\"mlflow\").setLevel(logging.DEBUG)` to see the full traceback.\n",
      "2023/07/27 21:43:29 INFO mlflow.utils.autologging_utils: Created MLflow autologging run with ID '94a4041b15504c7c9e591585ee97aacb', which will track hyperparameters, performance metrics, model artifacts, and lineage information for the current xgboost workflow\n",
      "2023/07/27 21:43:31 WARNING mlflow.models.model: Logging model metadata to the tracking server has failed. The model artifacts have been logged successfully under /home/zarko/PFE/prepoznavanje-emocija/lk-s-2023-prepoznavanje-emocija/mlruns/0/94a4041b15504c7c9e591585ee97aacb/artifacts. Set logging level to DEBUG via `logging.getLogger(\"mlflow\").setLevel(logging.DEBUG)` to see the full traceback.\n",
      "2023/07/27 21:43:31 INFO mlflow.utils.autologging_utils: Created MLflow autologging run with ID '9d46036eacb244c583f81d5d321a7ed5', which will track hyperparameters, performance metrics, model artifacts, and lineage information for the current xgboost workflow\n",
      "2023/07/27 21:43:34 WARNING mlflow.models.model: Logging model metadata to the tracking server has failed. The model artifacts have been logged successfully under /home/zarko/PFE/prepoznavanje-emocija/lk-s-2023-prepoznavanje-emocija/mlruns/0/9d46036eacb244c583f81d5d321a7ed5/artifacts. Set logging level to DEBUG via `logging.getLogger(\"mlflow\").setLevel(logging.DEBUG)` to see the full traceback.\n"
     ]
    },
    {
     "name": "stdout",
     "output_type": "stream",
     "text": [
      "[0.55555556 0.75       0.375      0.5        0.375      0.875\n",
      " 0.625      0.5        0.625      0.25       0.75       0.5\n",
      " 0.875      0.625      0.625      0.875      0.625      0.625\n",
      " 0.5        0.5       ]\n"
     ]
    }
   ],
   "source": [
    "# print ((cross_val_score(xgb, X_test, y_test, cv=20)))\n"
   ]
  },
  {
   "cell_type": "code",
   "execution_count": null,
   "metadata": {},
   "outputs": [],
   "source": []
  }
 ],
 "metadata": {
  "kernelspec": {
   "display_name": "Python 3",
   "language": "python",
   "name": "python3"
  },
  "language_info": {
   "codemirror_mode": {
    "name": "ipython",
    "version": 3
   },
   "file_extension": ".py",
   "mimetype": "text/x-python",
   "name": "python",
   "nbconvert_exporter": "python",
   "pygments_lexer": "ipython3",
   "version": "3.9.2"
  },
  "orig_nbformat": 4
 },
 "nbformat": 4,
 "nbformat_minor": 2
}
